Workbook

Sheet db_masterBarang
B1: id | C1: kode_barang | D1: kode_pending | E1: nama_barang | F1: panjang | G1: lebar | H1: tinggi | I1: hasil_dimensi | J1: exp_date | K1: lot | L1: keterangan
A2: =E2&J2&K2 -> Abacell 18 EC 10 X 1 ltr462040 | B2: ID1 | C2: KIU1 | D2: P1 | E2: Abacell 18 EC 10 X 1 ltr | F2: 10 | G2: 1 | H2: 1 | I2: 10 | J2: 46204 | K2: 0
A3: =E3&J3&K3 -> Abacell 18 EC 40 X 250 ml463570 | B3: ID2 | C3: KIU2 | D3: P2 | E3: Abacell 18 EC 40 X 250 ml | F3: 40 | G3: 1 | H3: 1 | I3: 40 | J3: 46357 | K3: 0
A4: =E4&J4&K4 -> Abacell 18 EC 50 X 100 ml460820 | B4: ID3 | C4: KIU3 | D4: P3 | E4: Abacell 18 EC 50 X 100 ml | F4: 50 | G4: 1 | H4: 1 | I4: 50 | J4: 46082 | K4: 0
A5: =E5&J5&K5 -> Abado 50 WP 20 X 20 X 10 gr467220 | B5: ID4 | C5: KIU4 | D5: P4 | E5: Abado 50 WP 20 X 20 X 10 gr | F5: 20 | G5: 20 | H5: 1 | I5: 400 | J5: 46722 | K5: 0
A6: =E6&J6&K6 -> Abado 50 WP 20 X 6 X 40 gr468440 | B6: ID5 | C6: KIU5 | D6: P5 | E6: Abado 50 WP 20 X 6 X 40 gr | F6: 20 | G6: 6 | H6: 1 | I6: 120 | J6: 46844 | K6: 0
A7: =E7&J7&K7 -> Abenz 22 EC 100 X 100 ml458090 | B7: ID6 | C7: KIU6 | D7: P6 | E7: Abenz 22 EC 100 X 100 ml | F7: 100 | G7: 1 | H7: 1 | I7: 100 | J7: 45809 | K7: 0
A8: =E8&J8&K8 -> Abenz 22 EC 100 X 100 ml469970 | B8: ID7 | C8: KIU7 | D8: P7 | E8: Abenz 22 EC 100 X 100 ml | F8: 100 | G8: 1 | H8: 1 | I8: 100 | J8: 46997 | K8: 0
A9: =E9&J9&K9 -> Abenz 22 EC 100 X 100 ml469350 | B9: ID8 | C9: KIU8 | D9: P8 | E9: Abenz 22 EC 100 X 100 ml | F9: 100 | G9: 1 | H9: 1 | I9: 100 | J9: 46935 | K9: 0
A10: =E10&J10&K10 -> Abenz 22 EC 40 X 250 ml468440 | B10: ID9 | C10: KIU9 | D10: P9 | E10: Abenz 22 EC 40 X 250 ml | F10: 40 | G10: 1 | H10: 1 | I10: 40 | J10: 46844 | K10: 0
A11: =E11&J11&K11 -> Abenz 22 EC 40 X 250 ml469970 | B11: ID10 | C11: KIU10 | D11: P10 | E11: Abenz 22 EC 40 X 250 ml | F11: 40 | G11: 1 | H11: 1 | I11: 40 | J11: 46997 | K11: 0
A12: =E12&J12&K12 -> Abojo 60 WP 10 X 20 X 50 gr471190 | B12: ID11 | C12: KIU11 | D12: P11 | E12: Abojo 60 WP 10 X 20 X 50 gr | F12: 10 | G12: 20 | H12: 1 | I12: 200 | J12: 47119 | K12: 0
A13: =E13&J13&K13 -> Abojo 60 WP 100 X 100 gr469660 | B13: ID12 | C13: KIU12 | D13: P12 | E13: Abojo 60 WP 100 X 100 gr | F13: 100 | G13: 1 | H13: 1 | I13: 100 | J13: 46966 | K13: 0
... A16: =E16&J16&K16 -> Accora 100 EC 20 X 500 ml460540 | B16: ID15 | C16: KIU15 | D16: P15 | E16: Accora 100 EC 20 X 500 ml | F16: 20 | G16: 1 | H16: 1 | I16: 20 | J16: 46054 | K16: 0
A17: =E17&J17&K17 -> Accu Kayaba Kering 12A - 12 Volt1/1/10000 | B17: ID16 | C17: KIU16 | D17: P16 | E17: Accu Kayaba Kering 12A - 12 Volt | F17: 1 | G17: 1 | H17: 1 | I17: 1 | J17: 1/1/1000 | K17: 0
A18: =E18&J18&K18 -> Accu Sprayer Elektrik 5L 12V 1.3A1/1/10000 | B18: ID17 | C18: KIU17 | D18: P17 | E18: Accu Sprayer Elektrik 5L 12V 1.3A | F18: 1 | G18: 1 | H18: 1 | I18: 1 | J18: 1/1/1000 | K18: 0
A19: =E19&J19&K19 -> Ace One 75 SP 25 X 400 gr470580 | B19: ID18 | C19: KIU18 | D19: P18 | E19: Ace One 75 SP 25 X 400 gr | F19: 25 | G19: 1 | H19: 1 | I19: 25 | J19: 47058 | K19: 0
A20: =E20&J20&K20 -> Ace One 75 SP 25 X 400 gr471500 | B20: ID19 | C20: KIU19 | D20: P19 | E20: Ace One 75 SP 25 X 400 gr | F20: 25 | G20: 1 | H20: 1 | I20: 25 | J20: 47150 | K20: 0
A21: =E21&J21&K21 -> Ace One 75 SP 50 X 100 gr469660 | B21: ID20 | C21: KIU20 | D21: P20 | E21: Ace One 75 SP 50 X 100 gr | F21: 50 | G21: 1 | H21: 1 | I21: 50 | J21: 46966 | K21: 0
A22: =E22&J22&K22 -> Ace One 75 SP 50 X 100 gr470580 | B22: ID21 | C22: KIU21 | D22: P21 | E22: Ace One 75 SP 50 X 100 gr | F22: 50 | G22: 1 | H22: 1 | I22: 50 | J22: 47058 | K22: 0
A23: =E23&J23&K23 -> Achlor 4/36 WP 60 X 100 gr464780 | B23: ID22 | C23: KIU22 | D23: P22 | E23: Achlor 4/36 WP 60 X 100 gr | F23: 60 | G23: 1 | H23: 1 | I23: 60 | J23: 46478 | K23: 0
A24: =E24&J24&K24 -> ACL 6 865 SL 25 X 400 ml466310 | B24: ID23 | C24: KIU23 | D24: P23 | E24: ACL 6 865 SL 25 X 400 ml | F24: 25 | G24: 1 | H24: 1 | I24: 25 | J24: 46631 | K24: 0
A25: =E25&J25&K25 -> ACL 6 865 SL 50 X 200 ml466000 | B25: ID24 | C25: KIU24 | D25: P24 | E25: ACL 6 865 SL 50 X 200 ml | F25: 50 | G25: 1 | H25: 1 | I25: 50 | J25: 46600 | K25: 0
A26: =E26&J26&K26 -> Acrobat WP 20 X 6 X 40 gr461130 | B26: ID25 | C26: KIU25 | D26: P25 | E26: Acrobat WP 20 X 6 X 40 gr | F26: 20 | G26: 6 | H26: 1 | I26: 120 | J26: 46113 | K26: 0
A27: =E27&J27&K27 -> Adrift 125 EC 40 X 250 ml455970 | B27: ID26 | C27: KIU26 | D27: P26 | E27: Adrift 125 EC 40 X 250 ml | F27: 40 | G27: 1 | H27: 1 | I27: 40 | J27: 45597 | K27: 0
A28: =E28&J28&K28 -> Adrift 125 EC 50 X 100 ml455970 | B28: ID27 | C28: KIU27 | D28: P27 | E28: Adrift 125 EC 50 X 100 ml | F28: 50 | G28: 1 | H28: 1 | I28: 50 | J28: 45597 | K28: 0
A29: =E29&J29&K29 -> Afonil 50 SC 100 X 100 ml456890 | B29: ID28 | C29: KIU28 | D29: P28 | E29: Afonil 50 SC 100 X 100 ml | F29: 100 | G29: 1 | H29: 1 | I29: 100 | J29: 45689 | K29: 0
A30: =E30&J30&K30 -> Afonil 50 SC 100 X 50 ml457170 | B30: ID29 | C30: KIU29 | D30: P29 | E30: Afonil 50 SC 100 X 50 ml | F30: 100 | G30: 1 | H30: 1 | I30: 100 | J30: 45717 | K30: 0
... A60: =E60&J60&K60 -> Akrostar 40 WP 60 X 40 gr461740 | B60: ID59 | C60: KIU59 | D60: P59 | E60: Akrostar 40 WP 60 X 40 gr | F60: 60 | G60: 1 | H60: 1 | I60: 60 | J60: 46174 | K60: 0
A61: =E61&J61&K61 -> Alat Kocor Pupuk Cair Jitu 20 Ltr1/1/10000 | B61: ID60 | C61: KIU60 | D61: P60 | E61: Alat Kocor Pupuk Cair Jitu 20 Ltr | F61: 1 | G61: 1 | H61: 1 | I61: 1 | J61: 1/1/1000 | K61: 0
A62: =E62&J62&K62 -> Alat Kocor Pupuk Cair Quda Karisma1/1/10000 | B62: ID61 | C62: KIU61 | D62: P61 | E62: Alat Kocor Pupuk Cair Quda Karisma | F62: 1 | G62: 1 | H62: 1 | I62: 1 | J62: 1/1/1000 | K62: 0
A63: =E63&J63&K63 -> Alat Kocor Pupuk Padat Quda Karisma1/1/10000 | B63: ID62 | C63: KIU62 | D63: P62 | E63: Alat Kocor Pupuk Padat Quda Karisma | F63: 1 | G63: 1 | H63: 1 | I63: 1 | J63: 1/1/1000 | K63: 0
A64: =E64&J64&K64 -> Alat Kocor Pupuk Padat Satagro 25 ltr1/1/10000 | B64: ID63 | C64: KIU63 | D64: P63 | E64: Alat Kocor Pupuk Padat Satagro 25 ltr | F64: 1 | G64: 1 | H64: 1 | I64: 1 | J64: 1/1/1000 | K64: 0
A65: =E65&J65&K65 -> Alat Pengikat Tanaman Yoto1/1/10000 | B65: ID64 | C65: KIU64 | D65: P64 | E65: Alat Pengikat Tanaman Yoto | F65: 1 | G65: 1 | H65: 1 | I65: 1 | J65: 1/1/1000 | K65: 0
A66: =E66&J66&K66 -> Alat Service YT 5L / 7L1/1/10000 | B66: ID65 | C66: KIU65 | D66: P65 | E66: Alat Service YT 5L / 7L | F66: 1 | G66: 1 | H66: 1 | I66: 1 | J66: 1/1/1000 | K66: 0
A67: =E67&J67&K67 -> Alat Tanam Jagung 1 Output Satagro MTB-006 6 X 1 pcs1/1/10000 | B67: ID66 | C67: KIU66 | D67: P66 | E67: Alat Tanam Jagung 1 Output Satagro MTB-006 6 X 1 pcs | F67: 6 | G67: 1 | H67: 1 | I67: 6 | J67: 1/1/1000 | K67: 0
A68: =E68&J68&K68 -> Alat Tanam Roll MTB-008 SS1/1/10000 | B68: ID67 | C68: KIU67 | D68: P67 | E68: Alat Tanam Roll MTB-008 SS | F68: 1 | G68: 1 | H68: 1 | I68: 1 | J68: 1/1/1000 | K68: 0
A69: =E69&J69&K69 -> Alat Tanam Roll MTB-010 SS1/1/10000 | B69: ID68 | C69: KIU68 | D69: P68 | E69: Alat Tanam Roll MTB-010 SS | F69: 1 | G69: 1 | H69: 1 | I69: 1 | J69: 1/1/1000 | K69: 0
A70: =E70&J70&K70 -> Alfatox 50 EC 20 X 400 ml (AGM)470880 | B70: ID69 | C70: KIU69 | D70: P69 | E70: Alfatox 50 EC 20 X 400 ml (AGM) | F70: 20 | G70: 1 | H70: 1 | I70: 20 | J70: 47088 | K70: 0
A71: =E71&J71&K71 -> Alfatox 50 EC 20 X 400 ml (AGM)471780 | B71: ID70 | C71: KIU70 | D71: P70 | E71: Alfatox 50 EC 20 X 400 ml (AGM) | F71: 20 | G71: 1 | H71: 1 | I71: 20 | J71: 47178 | K71: 0
...

Sheet db_barangZahir
B1: id | C1: kode_pending | D1: kode_barang | E1: nama_barang | F1: panjang | G1: lebar | H1: tinggi | I1: hasil_dimensi | J1: qty | K1: stok_box | L1: stok_pcs | M1: qty | N1: exp_date | O1: lot
A2: =E2&N2&O2 -> Abacell 18 EC 10 X 1 ltr462040 | B2: ID1 | C2: P1 | D2: KIU1 | E2: Abacell 18 EC 10 X 1 ltr | F2: 10 | G2: 1 | H2: 1 | I2: 10 | J2: 250 | K2: =ROUNDDOWN(J2/I2,0) -> 25 | L2: =J2-K2*I2 -> 0 | M2: 250 | N2: 46204 | O2: 0
A3: =E3&N3&O3 -> Abacell 18 EC 40 X 250 ml463570 | B3: ID2 | C3: P2 | D3: KIU2 | E3: Abacell 18 EC 40 X 250 ml | F3: 40 | G3: 1 | H3: 1 | I3: 40 | J3: 721 | K3: =ROUNDDOWN(J3/I3,0) -> 18 | L3: =J3-K3*I3 -> 1 | M3: 721 | N3: 46357 | O3: 0
A4: =E4&N4&O4 -> Abacell 18 EC 50 X 100 ml460820 | B4: ID3 | C4: P3 | D4: KIU3 | E4: Abacell 18 EC 50 X 100 ml | F4: 50 | G4: 1 | H4: 1 | I4: 50 | J4: 8185 | K4: =ROUNDDOWN(J4/I4,0) -> 163 | L4: =J4-K4*I4 -> 35 | M4: 8185 | N4: 46082 | O4: 0
A5: =E5&N5&O5 -> Abado 50 WP 20 X 20 X 10 gr467220 | B5: ID4 | C5: P4 | D5: KIU4 | E5: Abado 50 WP 20 X 20 X 10 gr | F5: 20 | G5: 20 | H5: 1 | I5: 400 | J5: 11563 | K5: =ROUNDDOWN(J5/I5,0) -> 28 | L5: =J5-K5*I5 -> 363 | M5: 11563 | N5: 46722 | O5: 0
A6: =E6&N6&O6 -> Abado 50 WP 20 X 6 X 40 gr468440 | B6: ID5 | C6: P5 | D6: KIU5 | E6: Abado 50 WP 20 X 6 X 40 gr | F6: 20 | G6: 6 | H6: 1 | I6: 120 | J6: 3372 | K6: =ROUNDDOWN(J6/I6,0) -> 28 | L6: =J6-K6*I6 -> 12 | M6: 3372 | N6: 46844 | O6: 0
A7: =E7&N7&O7 -> Abenz 22 EC 100 X 100 ml458090 | B7: ID6 | C7: P6 | D7: KIU6 | E7: Abenz 22 EC 100 X 100 ml | F7: 100 | G7: 1 | H7: 1 | I7: 100 | J7: 37 | K7: =ROUNDDOWN(J7/I7,0) -> 0 | L7: =J7-K7*I7 -> 37 | M7: 37 | N7: 45809 | O7: 0
A8: =E8&N8&O8 -> Abenz 22 EC 100 X 100 ml469970 | B8: ID7 | C8: P7 | D8: KIU7 | E8: Abenz 22 EC 100 X 100 ml | F8: 100 | G8: 1 | H8: 1 | I8: 100 | J8: 600 | K8: =ROUNDDOWN(J8/I8,0) -> 6 | L8: =J8-K8*I8 -> 0 | M8: 600 | N8: 46997 | O8: 0
A9: =E9&N9&O9 -> Abenz 22 EC 100 X 100 ml469350 | B9: ID8 | C9: P8 | D9: KIU8 | E9: Abenz 22 EC 100 X 100 ml | F9: 100 | G9: 1 | H9: 1 | I9: 100 | J9: 6450 | K9: =ROUNDDOWN(J9/I9,0) -> 64 | L9: =J9-K9*I9 -> 50 | M9: 6450 | N9: 46935 | O9: 0
A10: =E10&N10&O10 -> Abenz 22 EC 40 X 250 ml468440 | B10: ID9 | C10: P9 | D10: KIU9 | E10: Abenz 22 EC 40 X 250 ml | F10: 40 | G10: 1 | H10: 1 | I10: 40 | J10: 8 | K10: =ROUNDDOWN(J10/I10,0) -> 0 | L10: =J10-K10*I10 -> 8 | M10: 8 | N10: 46844 | O10: 0
A11: =E11&N11&O11 -> Abenz 22 EC 40 X 250 ml469970 | B11: ID10 | C11: P10 | D11: KIU10 | E11: Abenz 22 EC 40 X 250 ml | F11: 40 | G11: 1 | H11: 1 | I11: 40 | J11: 2000 | K11: =ROUNDDOWN(J11/I11,0) -> 50 | L11: =J11-K11*I11 -> 0 | M11: 2000 | N11: 46997 | O11: 0
A12: =E12&N12&O12 -> Abojo 60 WP 10 X 20 X 50 gr471190 | B12: ID11 | C12: P11 | D12: KIU11 | E12: Abojo 60 WP 10 X 20 X 50 gr | F12: 10 | G12: 20 | H12: 1 | I12: 200 | J12: 3488 | K12: =ROUNDDOWN(J12/I12,0) -> 17 | L12: =J12-K12*I12 -> 88 | M12: 3488 | N12: 47119 | O12: 0
A13: =E13&N13&O13 -> Abojo 60 WP 100 X 100 gr469660 | B13: ID12 | C13: P12 | D13: KIU12 | E13: Abojo 60 WP 100 X 100 gr | F13: 100 | G13: 1 | H13: 1 | I13: 100 | J13: 2594 | K13: =ROUNDDOWN(J13/I13,0) -> 25 | L13: =J13-K13*I13 -> 94 | M13: 2594 | N13: 46966 | O13: 0
... A16: =E16&N16&O16 -> Accora 100 EC 20 X 500 ml460540 | B16: ID15 | C16: P15 | D16: KIU15 | E16: Accora 100 EC 20 X 500 ml | F16: 20 | G16: 1 | H16: 1 | I16: 20 | J16: 115 | K16: =ROUNDDOWN(J16/I16,0) -> 5 | L16: =J16-K16*I16 -> 15 | M16: 115 | N16: 46054 | O16: 0
A17: =E17&N17&O17 -> Accu Kayaba Kering 12A - 12 Volt1/1/10000 | B17: ID16 | C17: P16 | D17: KIU16 | E17: Accu Kayaba Kering 12A - 12 Volt | F17: 1 | G17: 1 | H17: 1 | I17: 1 | J17: 1 | K17: =ROUNDDOWN(J17/I17,0) -> 1 | L17: =J17-K17*I17 -> 0 | M17: 1 | N17: 1/1/1000 | O17: 0
A18: =E18&N18&O18 -> Accu Sprayer Elektrik 5L 12V 1.3A1/1/10000 | B18: ID17 | C18: P17 | D18: KIU17 | E18: Accu Sprayer Elektrik 5L 12V 1.3A | F18: 1 | G18: 1 | H18: 1 | I18: 1 | J18: 85 | K18: =ROUNDDOWN(J18/I18,0) -> 85 | L18: =J18-K18*I18 -> 0 | M18: 85 | N18: 1/1/1000 | O18: 0
A19: =E19&N19&O19 -> Ace One 75 SP 25 X 400 gr470580 | B19: ID18 | C19: P18 | D19: KIU18 | E19: Ace One 75 SP 25 X 400 gr | F19: 25 | G19: 1 | H19: 1 | I19: 25 | J19: 1048 | K19: =ROUNDDOWN(J19/I19,0) -> 41 | L19: =J19-K19*I19 -> 23 | M19: 1048 | N19: 47058 | O19: 0
A20: =E20&N20&O20 -> Ace One 75 SP 25 X 400 gr471500 | B20: ID19 | C20: P19 | D20: KIU19 | E20: Ace One 75 SP 25 X 400 gr | F20: 25 | G20: 1 | H20: 1 | I20: 25 | J20: 1925 | K20: =ROUNDDOWN(J20/I20,0) -> 77 | L20: =J20-K20*I20 -> 0 | M20: 1925 | N20: 47150 | O20: 0
A21: =E21&N21&O21 -> Ace One 75 SP 50 X 100 gr469660 | B21: ID20 | C21: P20 | D21: KIU20 | E21: Ace One 75 SP 50 X 100 gr | F21: 50 | G21: 1 | H21: 1 | I21: 50 | J21: 3 | K21: =ROUNDDOWN(J21/I21,0) -> 0 | L21: =J21-K21*I21 -> 3 | M21: 3 | N21: 46966 | O21: 0
A22: =E22&N22&O22 -> Ace One 75 SP 50 X 100 gr470580 | B22: ID21 | C22: P21 | D22: KIU21 | E22: Ace One 75 SP 50 X 100 gr | F22: 50 | G22: 1 | H22: 1 | I22: 50 | J22: 1380 | K22: =ROUNDDOWN(J22/I22,0) -> 27 | L22: =J22-K22*I22 -> 30 | M22: 1380 | N22: 47058 | O22: 0
A23: =E23&N23&O23 -> Achlor 4/36 WP 60 X 100 gr464780 | B23: ID22 | C23: P22 | D23: KIU22 | E23: Achlor 4/36 WP 60 X 100 gr | F23: 60 | G23: 1 | H23: 1 | I23: 60 | J23: 120 | K23: =ROUNDDOWN(J23/I23,0) -> 2 | L23: =J23-K23*I23 -> 0 | M23: 120 | N23: 46478 | O23: 0
A24: =E24&N24&O24 -> ACL 6 865 SL 25 X 400 ml466310 | B24: ID23 | C24: P23 | D24: KIU23 | E24: ACL 6 865 SL 25 X 400 ml | F24: 25 | G24: 1 | H24: 1 | I24: 25 | J24: 171 | K24: =ROUNDDOWN(J24/I24,0) -> 6 | L24: =J24-K24*I24 -> 21 | M24: 171 | N24: 46631 | O24: 0
A25: =E25&N25&O25 -> ACL 6 865 SL 50 X 200 ml466000 | B25: ID24 | C25: P24 | D25: KIU24 | E25: ACL 6 865 SL 50 X 200 ml | F25: 50 | G25: 1 | H25: 1 | I25: 50 | J25: 572 | K25: =ROUNDDOWN(J25/I25,0) -> 11 | L25: =J25-K25*I25 -> 22 | M25: 572 | N25: 46600 | O25: 0
A26: =E26&N26&O26 -> Acrobat WP 20 X 6 X 40 gr461130 | B26: ID25 | C26: P25 | D26: KIU25 | E26: Acrobat WP 20 X 6 X 40 gr | F26: 20 | G26: 6 | H26: 1 | I26: 120 | J26: 7423 | K26: =ROUNDDOWN(J26/I26,0) -> 61 | L26: =J26-K26*I26 -> 103 | M26: 7423 | N26: 46113 | O26: 0
A27: =E27&N27&O27 -> Adrift 125 EC 40 X 250 ml455970 | B27: ID26 | C27: P26 | D27: KIU26 | E27: Adrift 125 EC 40 X 250 ml | F27: 40 | G27: 1 | H27: 1 | I27: 40 | J27: 230 | K27: =ROUNDDOWN(J27/I27,0) -> 5 | L27: =J27-K27*I27 -> 30 | M27: 230 | N27: 45597 | O27: 0
A28: =E28&N28&O28 -> Adrift 125 EC 50 X 100 ml455970 | B28: ID27 | C28: P27 | D28: KIU27 | E28: Adrift 125 EC 50 X 100 ml | F28: 50 | G28: 1 | H28: 1 | I28: 50 | J28: 104 | K28: =ROUNDDOWN(J28/I28,0) -> 2 | L28: =J28-K28*I28 -> 4 | M28: 104 | N28: 45597 | O28: 0
A29: =E29&N29&O29 -> Afonil 50 SC 100 X 100 ml456890 | B29: ID28 | C29: P28 | D29: KIU28 | E29: Afonil 50 SC 100 X 100 ml | F29: 100 | G29: 1 | H29: 1 | I29: 100 | J29: 1800 | K29: =ROUNDDOWN(J29/I29,0) -> 18 | L29: =J29-K29*I29 -> 0 | M29: 1800 | N29: 45689 | O29: 0
A30: =E30&N30&O30 -> Afonil 50 SC 100 X 50 ml457170 | B30: ID29 | C30: P29 | D30: KIU29 | E30: Afonil 50 SC 100 X 50 ml | F30: 100 | G30: 1 | H30: 1 | I30: 100 | J30: 2165 | K30: =ROUNDDOWN(J30/I30,0) -> 21 | L30: =J30-K30*I30 -> 65 | M30: 2165 | N30: 45717 | O30: 0
... A60: =E60&N60&O60 -> Akrostar 40 WP 60 X 40 gr461740 | B60: ID59 | C60: P59 | D60: KIU59 | E60: Akrostar 40 WP 60 X 40 gr | F60: 60 | G60: 1 | H60: 1 | I60: 60 | J60: 649 | K60: =ROUNDDOWN(J60/I60,0) -> 10 | L60: =J60-K60*I60 -> 49 | M60: 649 | N60: 46174 | O60: 0
A61: =E61&N61&O61 -> Alat Kocor Pupuk Cair Jitu 20 Ltr1/1/10000 | B61: ID60 | C61: P60 | D61: KIU60 | E61: Alat Kocor Pupuk Cair Jitu 20 Ltr | F61: 1 | G61: 1 | H61: 1 | I61: 1 | J61: 1 | K61: =ROUNDDOWN(J61/I61,0) -> 1 | L61: =J61-K61*I61 -> 0 | M61: 1 | N61: 1/1/1000 | O61: 0
A62: =E62&N62&O62 -> Alat Kocor Pupuk Cair Quda Karisma1/1/10000 | B62: ID61 | C62: P61 | D62: KIU61 | E62: Alat Kocor Pupuk Cair Quda Karisma | F62: 1 | G62: 1 | H62: 1 | I62: 1 | J62: 63 | K62: =ROUNDDOWN(J62/I62,0) -> 63 | L62: =J62-K62*I62 -> 0 | M62: 63 | N62: 1/1/1000 | O62: 0
A63: =E63&N63&O63 -> Alat Kocor Pupuk Padat Quda Karisma1/1/10000 | B63: ID62 | C63: P62 | D63: KIU62 | E63: Alat Kocor Pupuk Padat Quda Karisma | F63: 1 | G63: 1 | H63: 1 | I63: 1 | J63: 1 | K63: =ROUNDDOWN(J63/I63,0) -> 1 | L63: =J63-K63*I63 -> 0 | M63: 1 | N63: 1/1/1000 | O63: 0
A64: =E64&N64&O64 -> Alat Kocor Pupuk Padat Satagro 25 ltr1/1/10000 | B64: ID63 | C64: P63 | D64: KIU63 | E64: Alat Kocor Pupuk Padat Satagro 25 ltr | F64: 1 | G64: 1 | H64: 1 | I64: 1 | J64: 80 | K64: =ROUNDDOWN(J64/I64,0) -> 80 | L64: =J64-K64*I64 -> 0 | M64: 80 | N64: 1/1/1000 | O64: 0
A65: =E65&N65&O65 -> Alat Pengikat Tanaman Yoto1/1/10000 | B65: ID64 | C65: P64 | D65: KIU64 | E65: Alat Pengikat Tanaman Yoto | F65: 1 | G65: 1 | H65: 1 | I65: 1 | J65: 20 | K65: =ROUNDDOWN(J65/I65,0) -> 20 | L65: =J65-K65*I65 -> 0 | M65: 20 | N65: 1/1/1000 | O65: 0
A66: =E66&N66&O66 -> Alat Service YT 5L / 7L1/1/10000 | B66: ID65 | C66: P65 | D66: KIU65 | E66: Alat Service YT 5L / 7L | F66: 1 | G66: 1 | H66: 1 | I66: 1 | J66: 20 | K66: =ROUNDDOWN(J66/I66,0) -> 20 | L66: =J66-K66*I66 -> 0 | M66: 20 | N66: 1/1/1000 | O66: 0
A67: =E67&N67&O67 -> Alat Tanam Jagung 1 Output Satagro MTB-006 6 X 1 pcs1/1/10000 | B67: ID66 | C67: P66 | D67: KIU66 | E67: Alat Tanam Jagung 1 Output Satagro MTB-006 6 X 1 pcs | F67: 6 | G67: 1 | H67: 1 | I67: 6 | J67: 368 | K67: =ROUNDDOWN(J67/I67,0) -> 61 | L67: =J67-K67*I67 -> 2 | M67: 368 | N67: 1/1/1000 | O67: 0
A68: =E68&N68&O68 -> Alat Tanam Roll MTB-008 SS1/1/10000 | B68: ID67 | C68: P67 | D68: KIU67 | E68: Alat Tanam Roll MTB-008 SS | F68: 1 | G68: 1 | H68: 1 | I68: 1 | J68: 110 | K68: =ROUNDDOWN(J68/I68,0) -> 110 | L68: =J68-K68*I68 -> 0 | M68: 110 | N68: 1/1/1000 | O68: 0
A69: =E69&N69&O69 -> Alat Tanam Roll MTB-010 SS1/1/10000 | B69: ID68 | C69: P68 | D69: KIU68 | E69: Alat Tanam Roll MTB-010 SS | F69: 1 | G69: 1 | H69: 1 | I69: 1 | J69: 35 | K69: =ROUNDDOWN(J69/I69,0) -> 35 | L69: =J69-K69*I69 -> 0 | M69: 35 | N69: 1/1/1000 | O69: 0
A70: =E70&N70&O70 -> Alfatox 50 EC 20 X 400 ml (AGM)470880 | B70: ID69 | C70: P69 | D70: KIU69 | E70: Alfatox 50 EC 20 X 400 ml (AGM) | F70: 20 | G70: 1 | H70: 1 | I70: 20 | J70: 15 | K70: =ROUNDDOWN(J70/I70,0) -> 0 | L70: =J70-K70*I70 -> 15 | M70: 15 | N70: 47088 | O70: 0
A71: =E71&N71&O71 -> Alfatox 50 EC 20 X 400 ml (AGM)471780 | B71: ID70 | C71: P70 | D71: KIU70 | E71: Alfatox 50 EC 20 X 400 ml (AGM) | F71: 20 | G71: 1 | H71: 1 | I71: 20 | J71: 1980 | K71: =ROUNDDOWN(J71/I71,0) -> 99 | L71: =J71-K71*I71 -> 0 | M71: 1980 | N71: 47178 | O71: 0
...

Sheet db_pending
B1: id | C1: kode_pending | D1: kode_barang | E1: nama_barang | F1: exp_date | G1: lot | H1: qty
A2: =E2&F2&G2 -> Jagung Bisi 18 20 X 1 kg455743095HBS18 | B2: =VLOOKUP(A2,db_masterBarang!A:C,2,0) -> ID1817 | C2: P1817 | D2: KIU1817 | E2: Jagung Bisi 18 20 X 1 kg | F2: 45574 | G2: 3095HBS18 | H2: 2000
A3: =E3&F3&G3 -> Jagung Bisi 2 20 X 1 kg457732305HBS2 | B3: =VLOOKUP(A3,db_masterBarang!A:C,2,0) -> ID1899 | C3: P1899 | D3: KIU1899 | E3: Jagung Bisi 2 20 X 1 kg | F3: 45773 | G3: 2305HBS2 | H3: 100
A4: =E4&F4&G4 -> Jagung Bisi 321 20 X 1 kg (+Kaos)457982381HBS321 | B4: =VLOOKUP(A4,db_masterBarang!A:C,2,0) -> ID1903 | C4: P1903 | D4: KIU1903 | E4: Jagung Bisi 321 20 X 1 kg (+Kaos) | F4: 45798 | G4: 2381HBS321 | H4: 140
A5: =E5&F5&G5 -> Jagung Bisi 321 20 X 1 kg (+Kaos)457982381HBS321 | B5: =VLOOKUP(A5,db_masterBarang!A:C,2,0) -> ID1903 | C5: P1903 | D5: KIU1903 | E5: Jagung Bisi 321 20 X 1 kg (+Kaos) | F5: 45798 | G5: 2381HBS321 | H5: 40
A6: =E6&F6&G6 -> Jagung DK 771 20 X 1 kg (Bayer)455439CFA012099 | B6: =VLOOKUP(A6,db_masterBarang!A:C,2,0) -> ID1925 | C6: P1925 | D6: KIU1925 | E6: Jagung DK 771 20 X 1 kg (Bayer) | F6: 45543 | G6: 9CFA012099 | H6: 40
A7: =E7&F7&G7 -> Jagung DK 771 20 X 1 kg (Bayer)455439CFA012099 | B7: =VLOOKUP(A7,db_masterBarang!A:C,2,0) -> ID1925 | C7: P1925 | D7: KIU1925 | E7: Jagung DK 771 20 X 1 kg (Bayer) | F7: 45543 | G7: 9CFA012099 | H7: 300
A8: =E8&F8&G8 -> Jagung DK 771 20 X 1 kg (Bayer)455829CFA013003 | B8: =VLOOKUP(A8,db_masterBarang!A:C,2,0) -> ID1922 | C8: P1922 | D8: KIU1922 | E8: Jagung DK 771 20 X 1 kg (Bayer) | F8: 45582 | G8: 9CFA013003 | H8: 500
A9: =E9&F9&G9 -> Jagung NK 7202 20 X 1 kg4566619046175 | B9: =VLOOKUP(A9,db_masterBarang!A:C,2,0) -> ID1948 | C9: P1948 | D9: KIU1948 | E9: Jagung NK 7202 20 X 1 kg | F9: 45666 | G9: 19046175 | H9: 500
A10: =E10&F10&G10 -> Jagung NK 7202 20 X 1 kg4566619046175 | B10: =VLOOKUP(A10,db_masterBarang!A:C,2,0) -> ID1948 | C10: P1948 | D10: KIU1948 | E10: Jagung NK 7202 20 X 1 kg | F10: 45666 | G10: 19046175 | H10: 1140
A11: =E11&F11&G11 -> Jagung P27 Gajah 20 X 1 kg45641007CKMAFDNDC055 | B11: =VLOOKUP(A11,db_masterBarang!A:C,2,0) -> ID1964 | C11: P1964 | D11: KIU1964 | E11: Jagung P27 Gajah 20 X 1 kg | F11: 45641 | G11: 007CKMAFDNDC055 | H11: 40
A12: =E12&F12&G12 -> Jagung P27 Gajah 20 X 1 kg45641007CKMAFDNDC055 | B12: =VLOOKUP(A12,db_masterBarang!A:C,2,0) -> ID1964 | C12: P1964 | D12: KIU1964 | E12: Jagung P27 Gajah 20 X 1 kg | F12: 45641 | G12: 007CKMAFDNDC055 | H12: 200
A13: =E13&F13&G13 -> Abacell 18 EC 10 X 1 ltr462040 | B13: =VLOOKUP(A13,db_masterBarang!A:C,2,0) -> ID1 | C13: P1 | D13: KIU1 | E13: Abacell 18 EC 10 X 1 ltr | F13: 46204 | G13: 0 | H13: 10
A14: =E14&F14&G14 -> Abacell 18 EC 10 X 1 ltr462040 | B14: =VLOOKUP(A14,db_masterBarang!A:C,2,0) -> ID1 | C14: P1 | D14: KIU1 | E14: Abacell 18 EC 10 X 1 ltr | F14: 46204 | G14: 0 | H14: 100
A15: =E15&F15&G15 -> Abacell 18 EC 10 X 1 ltr462040 | B15: =VLOOKUP(A15,db_masterBarang!A:C,2,0) -> ID1 | C15: P1 | D15: KIU1 | E15: Abacell 18 EC 10 X 1 ltr | F15: 46204 | G15: 0 | H15: 9
A16: =E16&F16&G16 -> Abacell 18 EC 10 X 1 ltr462040 | B16: =VLOOKUP(A16,db_masterBarang!A:C,2,0) -> ID1 | C16: P1 | D16: KIU1 | E16: Abacell 18 EC 10 X 1 ltr | F16: 46204 | G16: 0 | H16: 140
A17: =E17&F17&G17 -> Abacell 18 EC 40 X 250 ml463570 | B17: =VLOOKUP(A17,db_masterBarang!A:C,2,0) -> ID2 | C17: P2 | D17: KIU2 | E17: Abacell 18 EC 40 X 250 ml | F17: 46357 | G17: 0 | H17: 40
A18: =E18&F18&G18 -> Abacell 18 EC 40 X 250 ml463570 | B18: =VLOOKUP(A18,db_masterBarang!A:C,2,0) -> ID2 | C18: P2 | D18: KIU2 | E18: Abacell 18 EC 40 X 250 ml | F18: 46357 | G18: 0 | H18: 40
A19: =E19&F19&G19 -> Abacell 18 EC 40 X 250 ml463570 | B19: =VLOOKUP(A19,db_masterBarang!A:C,2,0) -> ID2 | C19: P2 | D19: KIU2 | E19: Abacell 18 EC 40 X 250 ml | F19: 46357 | G19: 0 | H19: 120
A20: =E20&F20&G20 -> Abacell 18 EC 40 X 250 ml463570 | B20: =VLOOKUP(A20,db_masterBarang!A:C,2,0) -> ID2 | C20: P2 | D20: KIU2 | E20: Abacell 18 EC 40 X 250 ml | F20: 46357 | G20: 0 | H20: 5
A21: =E21&F21&G21 -> Abacell 18 EC 40 X 250 ml463570 | B21: =VLOOKUP(A21,db_masterBarang!A:C,2,0) -> ID2 | C21: P2 | D21: KIU2 | E21: Abacell 18 EC 40 X 250 ml | F21: 46357 | G21: 0 | H21: 80
A22: =E22&F22&G22 -> Abacell 18 EC 40 X 250 ml463570 | B22: =VLOOKUP(A22,db_masterBarang!A:C,2,0) -> ID2 | C22: P2 | D22: KIU2 | E22: Abacell 18 EC 40 X 250 ml | F22: 46357 | G22: 0 | H22: 80
A23: =E23&F23&G23 -> Abacell 18 EC 50 X 100 ml460820 | B23: =VLOOKUP(A23,db_masterBarang!A:C,2,0) -> ID3 | C23: P3 | D23: KIU3 | E23: Abacell 18 EC 50 X 100 ml | F23: 46082 | G23: 0 | H23: 100
A24: =E24&F24&G24 -> Abenz 22 EC 100 X 100 ml469350 | B24: =VLOOKUP(A24,db_masterBarang!A:C,2,0) -> ID8 | C24: P8 | D24: KIU8 | E24: Abenz 22 EC 100 X 100 ml | F24: 46935 | G24: 0 | H24: 500
... A303: =E303&F303&G303 -> Qiuonol 400 SL 42 x 50 ml (Sample)459920 | B303: =VLOOKUP(A303,db_masterBarang!A:C,2,0) -> ID1357 | C303: P1357 | D303: KIU1357 | E303: Qiuonol 400 SL 42 x 50 ml (Sample) | F303: 45992 | G303: 0 | H303: 122
A304: =E304&F304&G304 -> Alat Kocor Pupuk Cair Quda Karisma1/1/10000 | B304: =VLOOKUP(A304,db_masterBarang!A:C,2,0) -> ID61 | C304: P61 | D304: KIU61 | E304: Alat Kocor Pupuk Cair Quda Karisma | F304: 1/1/1000 | G304: 0 | H304: 1
A305: =E305&F305&G305 -> Alat Kocor Pupuk Cair Quda Karisma1/1/10000 | B305: =VLOOKUP(A305,db_masterBarang!A:C,2,0) -> ID61 | C305: P61 | D305: KIU61 | E305: Alat Kocor Pupuk Cair Quda Karisma | F305: 1/1/1000 | G305: 0 | H305: 1
A306: =E306&F306&G306 -> Alat Kocor Pupuk Cair Quda Karisma1/1/10000 | B306: =VLOOKUP(A306,db_masterBarang!A:C,2,0) -> ID61 | C306: P61 | D306: KIU61 | E306: Alat Kocor Pupuk Cair Quda Karisma | F306: 1/1/1000 | G306: 0 | H306: 1
A307: =E307&F307&G307 -> Alat Kocor Pupuk Padat Quda Karisma1/1/10000 | B307: =VLOOKUP(A307,db_masterBarang!A:C,2,0) -> ID62 | C307: P62 | D307: KIU62 | E307: Alat Kocor Pupuk Padat Quda Karisma | F307: 1/1/1000 | G307: 0 | H307: 3
A308: =E308&F308&G308 -> Alat Pengikat Tanaman Yoto1/1/10000 | B308: =VLOOKUP(A308,db_masterBarang!A:C,2,0) -> ID64 | C308: P64 | D308: KIU64 | E308: Alat Pengikat Tanaman Yoto | F308: 1/1/1000 | G308: 0 | H308: 2
A309: =E309&F309&G309 -> Gunting Gland 8" Bypass Pruner ,05-203 10 X 10 X 1 pcs1/1/10000 | B309: =VLOOKUP(A309,db_masterBarang!A:C,2,0) -> ID627 | C309: P627 | D309: KIU627 | E309: Gunting Gland 8" Bypass Pruner ,05-203 10 X 10 X 1 pcs | F309: 1/1/1000 | G309: 0 | H309: 10
A310: =E310&F310&G310 -> Mulsa Coboy 60 cm X 1 kg1/1/10000 | B310: =VLOOKUP(A310,db_masterBarang!A:C,2,0) -> ID1027 | C310: P1027 | D310: KIU1027 | E310: Mulsa Coboy 60 cm X 1 kg | F310: 1/1/1000 | G310: 0 | H310: 25
A311: =E311&F311&G311 -> Mulsa Karisma Q989 60 cm X 8 kg (Roll)1/1/10000 | B311: =VLOOKUP(A311,db_masterBarang!A:C,2,0) -> ID1054 | C311: P1054 | D311: KIU1054 | E311: Mulsa Karisma Q989 60 cm X 8 kg (Roll) | F311: 1/1/1000 | G311: 0 | H311: 6
A312: =E312&F312&G312 -> Mulsa Ori Gajah 0.3 50 cm X 18 kg (Roll)1/1/10000 | B312: =VLOOKUP(A312,db_masterBarang!A:C,2,0) -> ID1072 | C312: P1072 | D312: KIU1072 | E312: Mulsa Ori Gajah 0.3 50 cm X 18 kg (Roll) | F312: 1/1/1000 | G312: 0 | H312: 25
A313: =E313&F313&G313 -> Sprayer Apung Hokita1/1/10000 | B313: =VLOOKUP(A313,db_masterBarang!A:C,2,0) -> ID1565 | C313: P1565 | D313: KIU1565 | E313: Sprayer Apung Hokita | F313: 1/1/1000 | G313: 0 | H313: 1
A314: =E314&F314&G314 -> Sprayer Elektrik Joeragan 16 L Battery1/1/10000 | B314: =VLOOKUP(A314,db_masterBarang!A:C,2,0) -> ID1567 | C314: P1567 | D314: KIU1567 | E314: Sprayer Elektrik Joeragan 16 L Battery | F314: 1/1/1000 | G314: 0 | H314: 41
A315: =E315&F315&G315 -> Sprayer Elektrik Quda Karisma 10 L 1 X 6 pcs1/1/10000 | B315: =VLOOKUP(A315,db_masterBarang!A:C,2,0) -> ID1568 | C315: P1568 | D315: KIU1568 | E315: Sprayer Elektrik Quda Karisma 10 L 1 X 6 pcs | F315: 1/1/1000 | G315: 0 | H315: 1
... A330: =E330&F330&G330 -> Kaos MIA Trio Dahsyat1/1/10000 | B330: =VLOOKUP(A330,db_masterBarang!A:C,2,0) -> ID765 | C330: P765 | D330: KIU765 | E330: Kaos MIA Trio Dahsyat | F330: 1/1/1000 | G330: 0 | H330: 200

Sheet DIGITAL
A1: KODE | B1: DESCRIPTION | C1: UNIT | D1: NAMAGUDANG | E1: KELOMPOK | F1: JENIS | G1: MERK | H1: QTY | I1: QTYLOT | J1: NOMOR_LOT | K1: TGLPRODUKSI | L1: TGLKADALUARSA | M1: JENIS | P1: Nama | Q1: Jenis | S1: DESCRIPTION | T1: TGLKADALUARSA | U1: NOMOR_LOT | V1: QTYLOT | W1: Jenis
A2: QABAC01 | B2: Abacell 18 EC 10 X 1 ltr | C2: Btl | D2: Gdg. Ttp Sales | E2: Obat | F2: Insektisida | G2: Abacell 18 EC | H2: 250 | I2: 250 | J2: 10072023 | K2: 45309 | L2: 46204 | M2: Obat | P2: Abacell 18 EC 10 X 1 ltr | Q2: Obat | S2: Abacell 18 EC 10 X 1 ltr | T2: 46204 | U2: 0 | V2: 250 | W2: Obat
A3: QABAC04 | B3: Abacell 18 EC 40 X 250 ml | C3: Btl | D3: Gdg. Induk | E3: Obat | F3: Insektisida | G3: Abacell 18 EC | H3: 721 | I3: 721 | J3: 5122023 | K3: 45384 | L3: 46357 | M3: Obat | P3: Abacell 18 EC 40 X 250 ml | Q3: Obat | S3: Abacell 18 EC 40 X 250 ml | T3: 46357 | U3: 0 | V3: 721 | W3: Obat
A4: QABAC07 | B4: Abacell 18 EC 50 X 100 ml | C4: Btl | D4: Gdg. Induk | E4: Obat | F4: Insektisida | G4: Abacell 18 EC | H4: 8185 | I4: 8185 | J4: 30032023 | K4: 45324 | L4: 46082 | M4: Obat | P4: Abacell 18 EC 50 X 100 ml | Q4: Obat | S4: Abacell 18 EC 50 X 100 ml | T4: 46082 | U4: 0 | V4: 8185 | W4: Obat
A5: QABAD02 | B5: Abado 50 WP 20 X 20 X 10 gr | C5: Pack | D5: Gdg. Induk | E5: Obat | F5: Fungisida | G5: Abado 50 WP | H5: 11563 | I5: 11563 | J5: ADV349A006 | K5: 45174 | L5: 46722 | M5: Obat | P5: Abado 50 WP 20 X 20 X 10 gr | Q5: Obat | S5: Abado 50 WP 20 X 20 X 10 gr | T5: 46722 | U5: 0 | V5: 11563 | W5: Obat
A6: QABAD01 | B6: Abado 50 WP 20 X 6 X 40 gr | C6: Pack | D6: Gdg. Induk | E6: Obat | F6: Fungisida | G6: Abado 50 WP | H6: 3372 | I6: 3372 | J6: ADV108V010 | K6: 45146 | L6: 46844 | M6: Obat | P6: Abado 50 WP 20 X 6 X 40 gr | Q6: Obat | S6: Abado 50 WP 20 X 6 X 40 gr | T6: 46844 | U6: 0 | V6: 3372 | W6: Obat
A7: QABEN01 | B7: Abenz 22 EC 100 X 100 ml | C7: Btl | D7: Gdg. Induk | E7: Obat | F7: Insektisida | G7: Abenz 22 EC | H7: 7087 | I7: 37 | J7: ADV1551025 | K7: 44804 | L7: 45809 | M7: Obat | P7: Abenz 22 EC 100 X 100 ml | Q7: Obat | S7: Abenz 22 EC 100 X 100 ml | T7: 45809 | U7: 0 | V7: 37 | W7: Obat
A8: QABEN01 | B8: Abenz 22 EC 100 X 100 ml | C8: Btl | D8: Gdg. Induk | E8: Obat | F8: Insektisida | G8: Abenz 22 EC | H8: 7087 | I8: 600 | J8: ADV265V040 | K8: 45287 | L8: 46997 | M8: Obat | P8: Abenz 22 EC 100 X 100 ml | Q8: Obat | S8: Abenz 22 EC 100 X 100 ml | T8: 46997 | U8: 0 | V8: 600 | W8: Obat
A9: QABEN01 | B9: Abenz 22 EC 100 X 100 ml | C9: Btl | D9: Gdg. Induk | E9: Obat | F9: Insektisida | G9: Abenz 22 EC | H9: 7087 | I9: 6450 | J9: ADV0710180723 | K9: 45164 | L9: 46935 | M9: Obat | P9: Abenz 22 EC 100 X 100 ml | Q9: Obat | S9: Abenz 22 EC 100 X 100 ml | T9: 46935 | U9: 0 | V9: 6450 | W9: Obat
A10: QABEN02 | B10: Abenz 22 EC 40 X 250 ml | C10: Btl | D10: Gdg. Induk | E10: Obat | F10: Insektisida | G10: Abenz 22 EC | H10: 2008 | I10: 8 | J10: ADV117V049 | K10: 45146 | L10: 46844 | M10: Obat | P10: Abenz 22 EC 40 X 250 ml | Q10: Obat | S10: Abenz 22 EC 40 X 250 ml | T10: 46844 | U10: 0 | V10: 8 | W10: Obat
A11: QABEN02 | B11: Abenz 22 EC 40 X 250 ml | C11: Btl | D11: Gdg. Induk | E11: Obat | F11: Insektisida | G11: Abenz 22 EC | H11: 2008 | I11: 2000 | J11: ADV261V050 | K11: 45205 | L11: 46997 | M11: Obat | P11: Abenz 22 EC 40 X 250 ml | Q11: Obat | S11: Abenz 22 EC 40 X 250 ml | T11: 46997 | U11: 0 | V11: 2000 | W11: Obat
A12: QABOJ02 | B12: Abojo 60 WP 10 X 20 X 50 gr | C12: Pack | D12: Gdg. Induk | E12: Obat | F12: Moluskisida | G12: Abojo 60 WP | H12: 3488 | I12: 3488 | J12: ADV1200190124 | K12: 45409 | L12: 47119 | M12: Obat | P12: Abojo 60 WP 10 X 20 X 50 gr | Q12: Obat | S12: Abojo 60 WP 10 X 20 X 50 gr | T12: 47119 | U12: 0 | V12: 3488 | W12: Obat
A13: QABOJ01 | B13: Abojo 60 WP 100 X 100 gr | C13: Pack | D13: Gdg. Induk | E13: Obat | F13: Moluskisida | G13: Abojo 60 WP | H13: 2594 | I13: 2594 | J13: ADV0840270823 | K13: 45287 | L13: 46966 | M13: Obat | P13: Abojo 60 WP 100 X 100 gr | Q13: Obat | S13: Abojo 60 WP 100 X 100 gr | T13: 46966 | U13: 0 | V13: 2594 | W13: Obat
A14: QACAP02 | B14: Acapela System 280 SC 50 X 100 ml | C14: Btl | D14: Gdg. Induk | E14: Obat | F14: Insektisida | G14: Acapela System 280 SC | H14: 3273 | I14: 3273 | J14: C668N23003 | K14: 45317 | L14: 45689 | M14: Obat | P14: Abojo 60 WP 100 X 100 gr | Q14: Obat | S14: Acapela System 280 SC 50 X 100 ml | T14: 45689 | U14: 0 | V14: 3273 | W14: Obat
A15: AACCO03 | B15: Accora 100 EC 15 X 1 ltr (Sample) | C15: Btl | D15: Gdg. Induk | E15: No Group | F15: No Group | G15: No Group | H15: 1 | I15: 1 | J15: 2020 | K15: 44783 | L15: 45658 | M15: Sample | P15: Acapela System 280 SC 50 X 100 ml | Q15: Obat | S15: Accora 100 EC 15 X 1 ltr (Sample) | T15: 45658 | U15: 0 | V15: 1 | W15: Sample
A16: QACCO01 | B16: Accora 100 EC 20 X 500 ml | C16: Btl | D16: Gdg. Induk | E16: Obat | F16: Insektisida | G16: Accora 100 EC | H16: 115 | I16: 115 | J16: 2029 | K16: 44651 | L16: 46054 | M16: Obat | P16: Accora 100 EC 15 X 1 ltr (Sample) | Q16: Sample | S16: Accora 100 EC 20 X 500 ml | T16: 46054 | U16: 0 | V16: 115 | W16: Obat
A17: AACCU01 | B17: Accu Kayaba Kering 12A - 12 Volt | C17: Pcs | D17: Gdg. Induk | E17: Sarana Pertanian | F17: Sarana Pertanian | G17: No Group | H17: 1 | I17: 1 | J17: 0 | K17: 1/1/1000 | L17: 1/1/1000 | M17: Sparepart | P17: Accora 100 EC 20 X 500 ml | Q17: Obat | S17: Accu Kayaba Kering 12A - 12 Volt | T17: 1/1/1000 | U17: 0 | V17: 1 | W17: Sparepart
A18: QACCU05 | B18: Accu Sprayer Elektrik 5L 12V 1.3A | C18: Pcs | D18: Gdg. Induk | E18: No Group | F18: No Group | G18: No Group | H18: 85 | I18: 85 | J18: 0 | K18: 45341 | L18: 1/1/1000 | M18: Sarana Promosi | P18: Accu Kayaba Kering 12A - 12 Volt | Q18: Sparepart | S18: Accu Sprayer Elektrik 5L 12V 1.3A | T18: 1/1/1000 | U18: 0 | V18: 85 | W18: Sarana Promosi
A19: QACEO02 | B19: Ace One 75 SP 25 X 400 gr | C19: Pack | D19: Gdg. Induk | E19: Obat | F19: Insektisida | G19: Ace One 75 SP | H19: 2973 | I19: 1048 | J19: 23121801 | K19: 45300 | L19: 47058 | M19: Obat | P19: Accu Sprayer Elektrik 5L 12V 1.3A | Q19: Sarana Promosi | S19: Ace One 75 SP 25 X 400 gr | T19: 47058 | U19: 0 | V19: 1048 | W19: Obat
A20: QACEO02 | B20: Ace One 75 SP 25 X 400 gr | C20: Pack | D20: Gdg. Induk | E20: Obat | F20: Insektisida | G20: Ace One 75 SP | H20: 2973 | I20: 1925 | J20: 24031301 | K20: 45436 | L20: 47150 | M20: Obat | P20: Ace One 75 SP 25 X 400 gr | Q20: Obat | S20: Ace One 75 SP 25 X 400 gr | T20: 47150 | U20: 0 | V20: 1925 | W20: Obat
A21: QACEO04 | B21: Ace One 75 SP 50 X 100 gr | C21: Pack | D21: Gdg. Induk | E21: Obat | F21: Insektisida | G21: Ace One 75 SP | H21: 1383 | I21: 3 | J21: 23092601 | K21: 45300 | L21: 46966 | M21: Obat | P21: Ace One 75 SP 25 X 400 gr | Q21: Obat | S21: Ace One 75 SP 50 X 100 gr | T21: 46966 | U21: 0 | V21: 3 | W21: Obat
A22: QACEO04 | B22: Ace One 75 SP 50 X 100 gr | C22: Pack | D22: Gdg. Induk | E22: Obat | F22: Insektisida | G22: Ace One 75 SP | H22: 1383 | I22: 1380 | J22: 23122704 | K22: 45369 | L22: 47058 | M22: Obat | P22: Ace One 75 SP 50 X 100 gr | Q22: Obat | S22: Ace One 75 SP 50 X 100 gr | T22: 47058 | U22: 0 | V22: 1380 | W22: Obat
A23: QACHL01 | B23: Achlor 4/36 WP 60 X 100 gr | C23: Pack | D23: Gdg. Induk | E23: Obat | F23: Herbisida | G23: Achlor 47/36 WP | H23: 120 | I23: 120 | J23: ADV095A001 | K23: 45075 | L23: 46478 | M23: obat | P23: Ace One 75 SP 50 X 100 gr | Q23: Obat | S23: Achlor 4/36 WP 60 X 100 gr | T23: 46478 | U23: 0 | V23: 120 | W23: obat
A24: QACL02 | B24: ACL 6 865 SL 25 X 400 ml | C24: Btl | D24: Gdg. Induk | E24: Obat | F24: Herbisida | G24: ACL 6 865 SL | H24: 171 | I24: 42 | J24: 601220907016 | K24: 45309 | L24: 46631 | M24: Obat | P24: Achlor 4/36 WP 60 X 100 gr | Q24: obat | S24: ACL 6 865 SL 25 X 400 ml | T24: 46631 | U24: 0 | V24: 171 | W24: Obat
A25: QACL02 | B25: ACL 6 865 SL 25 X 400 ml | C25: Btl | D25: Gdg. Induk | E25: Obat | F25: Herbisida | G25: ACL 6 865 SL | H25: 171 | I25: 129 | J25: 601000000000 | K25: 44859 | L25: 46631 | M25: Obat | P25: ACL 6 865 SL 25 X 400 ml | Q25: Obat | S25: ACL 6 865 SL 50 X 200 ml | T25: 46600 | U25: 0 | V25: 572 | W25: Obat
A26: QACL01 | B26: ACL 6 865 SL 50 X 200 ml | C26: Btl | D26: Gdg. Induk | E26: Obat | F26: Herbisida | G26: ACL 6 865 SL | H26: 572 | I26: 43 | J26: 601220807018 | K26: 45309 | L26: 46600 | M26: Obat | P26: ACL 6 865 SL 25 X 400 ml | Q26: Obat | S26: Acrobat WP 20 X 6 X 40 gr | T26: 46113 | U26: 0 | V26: 7423 | W26: Obat
A27: QACL01 | B27: ACL 6 865 SL 50 X 200 ml | C27: Btl | D27: Gdg. Induk | E27: Obat | F27: Herbisida | G27: ACL 6 865 SL | H27: 572 | I27: 529 | J27: 601000000000 | K27: 44859 | L27: 46600 | M27: Obat | P27: ACL 6 865 SL 50 X 200 ml | Q27: Obat | S27: Adrift 125 EC 40 X 250 ml | T27: 45597 | U27: 0 | V27: 230 | W27: Obat
A28: QACRO03 | B28: Acrobat WP 20 X 6 X 40 gr | C28: Pack | D28: Gdg. Induk | E28: Obat | F28: Fungisida | G28: Acrobat 50 WP | H28: 7423 | I28: 103 | J28: 2405Q01003 | K28: 45379 | L28: 46113 | M28: Obat | P28: ACL 6 865 SL 50 X 200 ml | Q28: Obat | S28: Adrift 125 EC 50 X 100 ml | T28: 45597 | U28: 0 | V28: 104 | W28: Obat
A29: QACRO03 | B29: Acrobat WP 20 X 6 X 40 gr | C29: Pack | D29: Gdg. Induk | E29: Obat | F29: Fungisida | G29: Acrobat 50 WP | H29: 7423 | I29: 7320 | J29: 2405Q02001 | K29: 45379 | L29: 46113 | M29: Obat | P29: Acrobat WP 20 X 6 X 40 gr | Q29: Obat | S29: Afonil 50 SC 100 X 100 ml | T29: 45689 | U29: 0 | V29: 1800 | W29: Obat
A30: QADRI02 | B30: Adrift 125 EC 40 X 250 ml | C30: Btl | D30: Gdg. Induk | E30: Obat | F30: Fungisida | G30: Adrift 125 EC | H30: 230 | I30: 230 | J30: 6833 | K30: 45140 | L30: 45597 | M30: Obat | P30: Acrobat WP 20 X 6 X 40 gr | Q30: Obat | S30: Afonil 50 SC 100 X 50 ml | T30: 45717 | U30: 0 | V30: 2165 | W30: Obat
A31: QADRI01 | B31: Adrift 125 EC 50 X 100 ml | C31: Btl | D31: Gdg. Induk | E31: Obat | F31: Fungisida | G31: Adrift 125 EC | H31: 104 | I31: 104 | J31: 6833 | K31: 45140 | L31: 45597 | M31: Obat | P31: Adrift 125 EC 40 X 250 ml | Q31: Obat | S31: Afonil 50 SC 20 X 500 ml | T31: 45597 | U31: 0 | V31: 198 | W31: Obat
A32: QAFON04 | B32: Afonil 50 SC 100 X 100 ml | C32: Btl | D32: Gdg. Induk | E32: Obat | F32: Insektisida | G32: Afonil 50 SC | H32: 1800 | I32: 1800 | J32: 2202003 | K32: 44655 | L32: 45689 | M32: Obat | P32: Adrift 125 EC 50 X 100 ml | Q32: Obat | S32: Afonil 50 SC 40 X 250 ml | T32: 45597 | U32: 0 | V32: 15 | W32: Obat
A33: QAFON03 | B33: Afonil 50 SC 100 X 50 ml | C33: Btl | D33: Gdg. Induk | E33: Obat | F33: Insektisida | G33: Afonil 50 SC | H33: 2165 | I33: 2165 | J33: ADV074A001 | K33: 44655 | L33: 45717 | M33: Obat | P33: Afonil 50 SC 100 X 100 ml | Q33: Obat | S33: Afonil 50 SC 40 X 250 ml | T33: 46631 | U33: 0 | V33: 819 | W33: Obat
A34: QAFON01 | B34: Afonil 50 SC 20 X 500 ml | C34: Btl | D34: Gdg. Induk | E34: Obat | F34: Insektisida | G34: Afonil 50 SC | H34: 198 | I34: 198 | J34: 2111004 | K34: 44531 | L34: 45597 | M34: Obat | P34: Afonil 50 SC 100 X 50 ml | Q34: Obat | S34: Agapro 214/66 SL 40 X 200 ml | T34: 47027 | U34: 0 | V34: 640 | W34: Obat
A35: AAFON01 | B35: Afonil 50 SC 40 X 250 ml | C35: Btl | D35: Gdg. Induk | E35: Obat | F35: Insektisida | G35: Afonil 50 SC | H35: 188 | I35: 15 | J35: 2111055 | K35: 44849 | L35: 45597 | M35: Obat | P35: Afonil 50 SC 20 X 500 ml | Q35: Obat | S35: Agapro 214/66 SL 50 X 80 ml | T35: 47027 | U35: 0 | V35: 800 | W35: Obat
A36: AAFON01 | B36: Afonil 50 SC 40 X 250 ml | C36: Btl | D36: Gdg. Induk | E36: Obat | F36: Insektisida | G36: Afonil 50 SC | H36: 188 | I36: 173 | J36: 2103001 | K36: 45414 | L36: 46631 | M36: Obat | P36: Afonil 50 SC 40 X 250 ml | Q36: Obat | S36: Agil 100 EC 100 X 100 ml | T36: 47058 | U36: 0 | V36: 700 | W36: Obat
A37: QAFON02 | B37: Afonil 50 SC 40 X 250 ml | C37: Btl | D37: Gdg. Induk | E37: Obat | F37: Insektisida | G37: Afonil 50 SC | H37: 646 | I37: 209 | J37: 2009002 | K37: 45414 | L37: 46631 | M37: Obat | P37: Afonil 50 SC 40 X 250 ml | Q37: Obat | S37: Agil 100 EC 100 X 100 ml | T37: 47027 | U37: 0 | V37: 1500 | W37: Obat
A38: QAFON02 | B38: Afonil 50 SC 40 X 250 ml | C38: Btl | D38: Gdg. Induk | E38: Obat | F38: Insektisida | G38: Afonil 50 SC | H38: 646 | I38: 437 | J38: 2103001 | K38: 45414 | L38: 46631 | M38: Obat | P38: Afonil 50 SC 40 X 250 ml | Q38: Obat | S38: Agil 100 EC 100 X 100 ml | T38: 46966 | U38: 0 | V38: 3005 | W38: Obat
A39: QAGAP02 | B39: Agapro 214/66 SL 40 X 200 ml | C39: Btl | D39: Gdg. Induk | E39: No Group | F39: No Group | G39: No Group | H39: 640 | I39: 640 | J39: 7733W3001 | K39: 45345 | L39: 47027 | M39: Obat | P39: Afonil 50 SC 40 X 250 ml | Q39: Obat | S39: Agil 100 EC 40 X 250 ml | T39: 47088 | U39: 0 | V39: 22 | W39: Obat
A40: QAGAP01 | B40: Agapro 214/66 SL 50 X 80 ml | C40: Btl | D40: Gdg. Induk | E40: No Group | F40: No Group | G40: No Group | H40: 800 | I40: 800 | J40: 78473W3001 | K40: 45345 | L40: 47027 | M40: Obat | P40: Agapro 214/66 SL 40 X 200 ml | Q40: Obat | S40: Agil 100 EC 40 X 250 ml | T40: 47209 | U40: 0 | V40: 3600 | W40: Obat
...

Sheet BENIH
A1: KODE | B1: DESCRIPTION | C1: UNIT | D1: NAMAGUDANG | E1: KELOMPOK | F1: JENIS | G1: MERK | H1: QTY | I1: QTYLOT | J1: NOMOR_LOT | K1: TGLPRODUKSI | L1: TGLKADALUARSA | M1: JENIS | O1: DESCRIPTION | P1: TGLKADALUARSA | Q1: NOMOR_LOT | R1: QTYLOT
A2: QBAWA01 | B2: Bawang Bahana 12 X 10 X 20 gr | C2: Pack | D2: Gdg. Induk | E2: Benih Horti | F2: Benih Bawang | G2: Bawang Bahana | H2: 20 | I2: 20 | J2: 411230717 | K2: 45243 | L2: 45565 | M2: Benih Horti | O2: Bawang Bahana 12 X 10 X 20 gr | P2: 45565 | Q2: 411230717 | R2: 20
A3: QBAYA25 | B3: Bayam Belang 35 X 500 gr | C3: Pack | D3: Gdg. Induk | E3: Benih Horti | F3: Benih Bayam | G3: Bayam Belang | H3: 524 | I3: 35 | J3: 67102320 | K3: 45293 | L3: 45792 | M3: Benih Horti | O3: Bayam Belang 35 X 500 gr | P3: 45792 | Q3: 67102320 | R3: 35
A4: QBAYA25 | B4: Bayam Belang 35 X 500 gr | C4: Pack | D4: Gdg. Induk | E4: Benih Horti | F4: Benih Bayam | G4: Bayam Belang | H4: 524 | I4: 139 | J4: 67082309 | K4: 45205 | L4: 45730 | M4: Benih Horti | O4: Bayam Belang 35 X 500 gr | P4: 45730 | Q4: 67082309 | R4: 139
A5: QBAYA25 | B5: Bayam Belang 35 X 500 gr | C5: Pack | D5: Gdg. Induk | E5: Benih Horti | F5: Benih Bayam | G5: Bayam Belang | H5: 524 | I5: 350 | J5: 67092310 | K5: 45206 | L5: 45745 | M5: Benih Horti | O5: Bayam Belang 35 X 500 gr | P5: 45745 | Q5: 67092310 | R5: 350
A6: QBAYA04 | B6: Bayam Belang 90 X 100 gr | C6: Pack | D6: Gdg. Induk | E6: Benih Horti | F6: Benih Bayam | G6: Bayam Belang | H6: 206 | I6: 206 | J6: 67072306 | K6: 45142 | L6: 45689 | M6: Benih Horti | O6: Bayam Belang 90 X 100 gr | P6: 45689 | Q6: 67072306 | R6: 206
A7: QBUNC05 | B7: Buncis Elastis 30 X 500 gr | C7: Pack | D7: Gdg. Induk | E7: Benih Horti | F7: Benih Buncis | G7: Buncis Elastis | H7: 300 | I7: 300 | J7: 384102301 | K7: 45442 | L7: 45964 | M7: Benih Horti | O7: Buncis Elastis 30 X 500 gr | P7: 45964 | Q7: 384102301 | R7: 300
A8: QCABE01 | B8: Cabe Balebat F1 12 X 15 X 10 gr | C8: Pack | D8: Gdg. Induk | E8: Benih Horti | F8: Benih Cabe Besar | G8: Cabe Balebat F1 | H8: 268 | I8: 268 | J8: 188052301 | K8: 45157 | L8: 45660 | M8: Benih Horti | O8: Cabe Balebat F1 12 X 15 X 10 gr | P8: 45660 | Q8: 188052301 | R8: 268
A9: QCABE54 | B9: Cabe Columbus 20 X 12 X 10 gr | C9: Pack | D9: Gdg. Induk | E9: Benih Horti | F9: Benih Cabe Besar | G9: Cabe Columbus | H9: 381 | I9: 72 | J9: 318344 | K9: 45304 | L9: 45843 | M9: Benih Horti | O9: Cabe Columbus 20 X 12 X 10 gr | P9: 45843 | Q9: 318344 | R9: 72
A10: QCABE54 | B10: Cabe Columbus 20 X 12 X 10 gr | C10: Pack | D10: Gdg. Induk | E10: Benih Horti | F10: Benih Cabe Besar | G10: Cabe Columbus | H10: 381 | I10: 132 | J10: 418442 | K10: 45353 | L10: 45896 | M10: Benih Horti | O10: Cabe Columbus 20 X 12 X 10 gr | P10: 45896 | Q10: 418442 | R10: 132
A11: QCABE54 | B11: Cabe Columbus 20 X 12 X 10 gr | C11: Pack | D11: Gdg. Induk | E11: Benih Horti | F11: Benih Cabe Besar | G11: Cabe Columbus | H11: 381 | I11: 177 | J11: 317532 | K11: 45279 | L11: 45809 | M11: Benih Horti | O11: Cabe Columbus 20 X 12 X 10 gr | P11: 45809 | Q11: 317532 | R11: 177
A12: QCABE06 | B12: Cabe Genie 12 X 15 X 10 gr | C12: Pack | D12: Gdg. Induk | E12: Benih Horti | F12: Benih Cabe Rawit | G12: Cabe Genie | H12: 3874 | I12: 65 | J12: 27122350 | K12: 45299 | L12: 45834 | M12: Benih Horti | O12: Cabe Genie 12 X 15 X 10 gr | P12: 45834 | Q12: 27122350 | R12: 65
A13: QCABE06 | B13: Cabe Genie 12 X 15 X 10 gr | C13: Pack | D13: Gdg. Induk | E13: Benih Horti | F13: Benih Cabe Rawit | G13: Cabe Genie | H13: 3874 | I13: 115 | J13: 27122349 | K13: 45299 | L13: 45831 | M13: Benih Horti | O13: Cabe Genie 12 X 15 X 10 gr | P13: 45831 | Q13: 27122349 | R13: 115
... A32: QCAUL03 | B32: Cauli Flower White Shot 25 X 10 X 10 gr | C32: Pack | D32: Gdg. Induk | E32: Benih Horti | F32: Benih Cauli Flower | G32: Cauli Flower White Shot | H32: 165 | I32: 165 | J32: 10013423 | K32: 45453 | L32: 45919 | M32: Benih Horti | O32: Cauli Flower White Shot 25 X 10 X 10 gr | P32: 45919 | Q32: 10013423 | R32: 165
A33: QJAGU63 | B33: Jagung ADV 132 20 X 1 kg | C33: Pack | D33: Gdg. Induk | E33: Benih Jagung | F33: Jagung Hibrida | G33: Jagung ADV 132 | H33: 23996 | I33: 16 | J33: LLK1A1013 | K33: 45261 | L33: 45503 | M33: Benih Jagung | O33: Jagung ADV 132 20 X 1 kg | P33: 45503 | Q33: LLK1A1013 | R33: 16
A34: QJAGU63 | B34: Jagung ADV 132 20 X 1 kg | C34: Pack | D34: Gdg. Induk | E34: Benih Jagung | F34: Jagung Hibrida | G34: Jagung ADV 132 | H34: 23996 | I34: 140 | J34: LLK1A3016 | K34: 45428 | L34: 45654 | M34: Benih Jagung | O34: Jagung ADV 132 20 X 1 kg | P34: 45654 | Q34: LLK1A3016 | R34: 140
A35: QJAGU63 | B35: Jagung ADV 132 20 X 1 kg | C35: Pack | D35: Gdg. Induk | E35: Benih Jagung | F35: Jagung Hibrida | G35: Jagung ADV 132 | H35: 23996 | I35: 2860 | J35: LLK1A1020 | K35: 45379 | L35: 45638 | M35: Benih Jagung | O35: Jagung ADV 132 20 X 1 kg | P35: 45638 | Q35: LLK1A1020 | R35: 2860
A36: QJAGU63 | B36: Jagung ADV 132 20 X 1 kg | C36: Pack | D36: Gdg. Induk | E36: Benih Jagung | F36: Jagung Hibrida | G36: Jagung ADV 132 | H36: 23996 | I36: 3980 | J36: LLK1A1017 | K36: 45377 | L36: 45514 | M36: Benih Jagung | O36: Jagung ADV 132 20 X 1 kg | P36: 45514 | Q36: LLK1A1017 | R36: 3980
A37: QJAGU63 | B37: Jagung ADV 132 20 X 1 kg | C37: Pack | D37: Gdg. Induk | E37: Benih Jagung | F37: Jagung Hibrida | G37: Jagung ADV 132 | H37: 23996 | I37: 4860 | J37: LLK1A3015 | K37: 45428 | L37: 45654 | M37: Benih Jagung | O37: Jagung ADV 132 20 X 1 kg | P37: 45654 | Q37: LLK1A3015 | R37: 4860
A38: QJAGU63 | B38: Jagung ADV 132 20 X 1 kg | C38: Pack | D38: Gdg. Induk | E38: Benih Jagung | F38: Jagung Hibrida | G38: Jagung ADV 132 | H38: 23996 | I38: 12140 | J38: LLK1A1019 | K38: 45378 | L38: 45638 | M38: Benih Jagung | O38: Jagung ADV 132 20 X 1 kg | P38: 45638 | Q38: LLK1A1019 | R38: 12140
A39: QJAGU03 | B39: Jagung Bisi 18 20 X 1 kg | C39: Pack | D39: Gdg. Induk | E39: Benih Jagung | F39: Jagung Hibrida | G39: Jagung Bisi 18 | H39: 1518 | I39: 18 | J39: 3079HBS18 | K39: 45236 | L39: 45571 | M39: Benih Jagung | O39: Jagung Bisi 18 20 X 1 kg | P39: 45571 | Q39: 3079HBS18 | R39: 18
A40: QJAGU03 | B40: Jagung Bisi 18 20 X 1 kg | C40: Pack | D40: Gdg. Belakang3 | E40: Benih Jagung | F40: Jagung Hibrida | G40: Jagung Bisi 18 | H40: 249500 | I40: 120 | J40: 3175HBS18 | K40: 45247 | L40: 45596 | M40: Benih Jagung | O40: Jagung Bisi 18 20 X 1 kg | P40: 45596 | Q40: 3175HBS18 | R40: 120
A41: QJAGU03 | B41: Jagung Bisi 18 20 X 1 kg | C41: Pack | D41: Gdg.Belakang2 | E41: Benih Jagung | F41: Jagung Hibrida | G41: Jagung Bisi 18 | H41: 218760 | I41: 160 | J41: 4039HBS18 | K41: 45283 | L41: 45638 | M41: Benih Jagung | O41: Jagung Bisi 18 20 X 1 kg | P41: 45638 | Q41: 4039HBS18 | R41: 1200
A42: QJAGU03 | B42: Jagung Bisi 18 20 X 1 kg | C42: Pack | D42: Gdg. Belakang1 | E42: Benih Jagung | F42: Jagung Hibrida | G42: Jagung Bisi 18 | H42: 307680 | I42: 220 | J42: 3163HBS18 | K42: 45247 | L42: 45585 | M42: Benih Jagung | O42: Jagung Bisi 18 20 X 1 kg | P42: 45585 | Q42: 3163HBS18 | R42: 21440
A43: QJAGU03 | B43: Jagung Bisi 18 20 X 1 kg | C43: Pack | D43: Gdg. Belakang3 | E43: Benih Jagung | F43: Jagung Hibrida | G43: Jagung Bisi 18 | H43: 249500 | I43: 220 | J43: 3189HBS18 | K43: 45247 | L43: 45596 | M43: Benih Jagung | O43: Jagung Bisi 18 20 X 1 kg | P43: 45596 | Q43: 3189HBS18 | R43: 15220
A44: QJAGU03 | B44: Jagung Bisi 18 20 X 1 kg | C44: Pack | D44: Gdg.Belakang2 | E44: Benih Jagung | F44: Jagung Hibrida | G44: Jagung Bisi 18 | H44: 218760 | I44: 400 | J44: 4035HBS18 | K44: 45283 | L44: 45635 | M44: Benih Jagung | O44: Jagung Bisi 18 20 X 1 kg | P44: 45635 | Q44: 4035HBS18 | R44: 400
... A165: QJAGU68 | B165: Jagung DK 771 20 X 1 kg (Bayer) | C165: Pack | D165: Gdg. Induk | E165: Benih Jagung | F165: Jagung Hibrida | G165: Jagung DK 771 | H165: 15022 | I165: 539 | J165: 9CFA013004 | K165: 45244 | L165: 45582 | M165: Benih Jagung | O165: Jagung DK 9209C 20 X 1 kg (Bayer) | P165: 45619 | Q165: 2CFB013035 | R165: 6140
A166: QJAGU68 | B166: Jagung DK 771 20 X 1 kg (Bayer) | C166: Pack | D166: Gdg. Induk | E166: Benih Jagung | F166: Jagung Hibrida | G166: Jagung DK 771 | H166: 15022 | I166: 1004 | J166: 9CFA013008 | K166: 45244 | L166: 45582 | M166: Benih Jagung | O166: Jagung Manis Exsotic 40 X 250 gr | P166: 45710 | Q166: 324.0829 | R166: 1160
A167: QJAGU68 | B167: Jagung DK 771 20 X 1 kg (Bayer) | C167: Pack | D167: Gdg. Induk | E167: Benih Jagung | F167: Jagung Hibrida | G167: Jagung DK 771 | H167: 15022 | I167: 1058 | J167: 9CFA013003 | K167: 45244 | L167: 45582 | M167: Benih Jagung | O167: Jagung Manis Golden Boy 20 X 500 gr | P167: 45689 | Q167: 316451 | R167: 160
A168: QJAGU68 | B168: Jagung DK 771 20 X 1 kg (Bayer) | C168: Pack | D168: Gdg. Induk | E168: Benih Jagung | F168: Jagung Hibrida | G168: Jagung DK 771 | H168: 15022 | I168: 2000 | J168: 9CFA013020 | K168: 45455 | L168: 45612 | M168: Benih Jagung | O168: Jagung Manis Madu-59 F1 20 X 250 gr | P168: 45708 | Q168: MJS2A1001 | R168: 200
A169: QJAGU68 | B169: Jagung DK 771 20 X 1 kg (Bayer) | C169: Pack | D169: Gdg. Induk | E169: Benih Jagung | F169: Jagung Hibrida | G169: Jagung DK 771 | H169: 15022 | I169: 5000 | J169: 9CFA013018 | K169: 45455 | L169: 45612 | M169: Benih Jagung | O169: Jagung Manis Master Sweet 45 20 X 500 gr | P169: 45597 | Q169: 45316450 | R169: 1
A170: QJAGU68 | B170: Jagung DK 771 20 X 1 kg (Bayer) | C170: Pack | D170: Gdg. Induk | E170: Benih Jagung | F170: Jagung Hibrida | G170: Jagung DK 771 | H170: 15022 | I170: 5400 | J170: 9CFA012099 | K170: 45230 | L170: 45543 | M170: Benih Jagung | O170: Jagung Manis Master Sweet 45 20 X 500 gr | P170: 45689 | Q170: 45-3-314518 | R170: 100
A171: QJAGU78 | B171: Jagung DK 9209C 20 X 1 kg (Bayer) | C171: Pack | D171: Gdg. Induk | E171: Benih Jagung | F171: Jagung Hibrida | G171: Jagung DEKALB 9209C | H171: 17590 | I171: 80 | J171: 2CFB013032 | K171: 45436 | L171: 45619 | M171: Benih Jagung | O171: Jagung Manis Master Sweet 45 20 X 500 gr | P171: 45689 | Q171: 45-315089 | R171: 1040
A172: QJAGU78 | B172: Jagung DK 9209C 20 X 1 kg (Bayer) | C172: Pack | D172: Gdg. Induk | E172: Benih Jagung | F172: Jagung Hibrida | G172: Jagung DEKALB 9209C | H172: 17590 | I172: 80 | J172: 2CFB013026 | K172: 45384 | L172: 45619 | M172: Benih Jagung | O172: Jagung Manis Sweet Lady 27 20 X 500 gr | P172: 45689 | Q172: 27-316472 | R172: 1170
A173: QJAGU78 | B173: Jagung DK 9209C 20 X 1 kg (Bayer) | C173: Pack | D173: Gdg. Induk | E173: Benih Jagung | F173: Jagung Hibrida | G173: Jagung DEKALB 9209C | H173: 17590 | I173: 240 | J173: 2CFB013030 | K173: 45384 | L173: 45619 | M173: Benih Jagung | O173: Jagung NK 212 20 X 1 kg | P173: 45700 | Q173: 19352424 | R173: 2180
A174: QJAGU78 | B174: Jagung DK 9209C 20 X 1 kg (Bayer) | C174: Pack | D174: Gdg. Induk | E174: Benih Jagung | F174: Jagung Hibrida | G174: Jagung DEKALB 9209C | H174: 17590 | I174: 590 | J174: 2CFB013029 | K174: 45289 | L174: 45619 | M174: Benih Jagung | O174: Jagung NK 212 20 X 1 kg | P174: 45748 | Q174: 19237373 | R174: 3520
A175: QJAGU78 | B175: Jagung DK 9209C 20 X 1 kg (Bayer) | C175: Pack | D175: Gdg. Induk | E175: Benih Jagung | F175: Jagung Hibrida | G175: Jagung DEKALB 9209C | H175: 17590 | I175: 700 | J175: 2CFB013028 | K175: 45384 | L175: 45619 | M175: Benih Jagung | O175: Jagung NK 212 20 X 1 kg | P175: 45789 | Q175: 19350401 | R175: 5560
A176: QJAGU78 | B176: Jagung DK 9209C 20 X 1 kg (Bayer) | C176: Pack | D176: Gdg. Induk | E176: Benih Jagung | F176: Jagung Hibrida | G176: Jagung DEKALB 9209C | H176: 17590 | I176: 1040 | J176: 2CFB013031 | K176: 45423 | L176: 45619 | M176: Benih Jagung | O176: Jagung NK 212 20 X 1 kg | P176: 45748 | Q176: 19237375 | R176: 7480
A177: QJAGU78 | B177: Jagung DK 9209C 20 X 1 kg (Bayer) | C177: Pack | D177: Gdg. Induk | E177: Benih Jagung | F177: Jagung Hibrida | G177: Jagung DEKALB 9209C | H177: 17590 | I177: 1600 | J177: 2CFB013034 | K177: 45384 | L177: 45619 | M177: Benih Jagung | O177: Jagung NK 212 20 X 1 kg | P177: 45784 | Q177: 19337579 | R177: 15480
A178: QJAGU78 | B178: Jagung DK 9209C 20 X 1 kg (Bayer) | C178: Pack | D178: Gdg. Induk | E178: Benih Jagung | F178: Jagung Hibrida | G178: Jagung DEKALB 9209C | H178: 17590 | I178: 2260 | J178: 2CFB013036 | K178: 45384 | L178: 45619 | M178: Benih Jagung | O178: Jagung NK 7202 20 X 1 kg | P178: 45666 | Q178: 19046175 | R178: 10
...

Sheet barang
A1: INVENTOR.DESCRIPTION | B1: INVENTOR.KODE | C1: INVENTOR.PANJANG | D1: INVENTOR.LEBAR | E1: INVENTOR.TINGGI | F1: INVENTOR.BERAT | G1: INVENTOR.KUBIKASI | H1: UNIT.UNIT
A2: Abacell 18 EC 10 X 1 ltr | B2: QABAC01 | C2: 10 | D2: 1 | E2: 1 | F2: 1253 | G2: 0.0018722 | H2: Btl
A3: Abacell 18 EC 100 X 100 ml (tdk terpakai) | B3: QABAC02 | C3: 100 | D3: 1 | E3: 1 | F3: 70.6 | G3: 0.00014931 | H3: Btl
A4: Abacell 18 EC 20 X 500 ml | B4: QABAC03 | C4: 20 | D4: 1 | E4: 1 | F4: 645.5 | G4: 0.0010695 | H4: Btl
A5: Abacell 18 EC 40 X 250 ml | B5: QABAC04 | C5: 40 | D5: 1 | E5: 1 | F5: 340.25 | G5: 0.0005957 | H5: Btl
A6: Abacell 18 EC 50 X 100 ml | B6: QABAC07 | C6: 50 | D6: 1 | E6: 1 | F6: 139.4 | G6: 0.000258375 | H6: Btl
A7: Abacyper 30/125 EC 24 X 200 ml | B7: QABAC06 | C7: 24 | D7: 1 | E7: 1 | F7: 266.25 | G7: 0.000836 | H7: Btl
A8: Abacyper 30/125 EC 48 X 100 ml | B8: QABAC05 | C8: 48 | D8: 1 | E8: 1 | F8: 136.45833 | G8: 0.000328 | H8: Btl
A9: Abado 50 WP 20 X 20 X 10 gr | B9: QABAD02 | C9: 20 | D9: 20 | E9: 1 | F9: 16.3 | G9: 8.55e-05 | H9: Pack
A10: Abado 50 WP 20 X 6 X 40 gr | B10: QABAD01 | C10: 20 | D10: 6 | E10: 1 | F10: 60.8 | G10: 0.0003844 | H10: Pack
A11: Abastar 290 SC 40 X 250 ml | B11: QABAS02 | C11: 40 | D11: 1 | E11: 1 | F11: 350 | G11: 0.0006383 | H11: Btl
A12: Abastar 290 SC 50 X 100 ml | B12: QABAS01 | C12: 50 | D12: 1 | E12: 1 | F12: 0 | G12: 0 | H12: Btl
A13: Abenz 22 EC 100 X 100 ml | B13: QABEN01 | C13: 100 | D13: 1 | E13: 1 | F13: 126 | G13: 0.000344 | H13: Btl
... A4182: Tabung Pompa Komplit 14 ltr | B4182: ATABU01 | C4182: 1 | D4182: 1 | E4182: 1 | F4182: 0 | G4182: 0 | H4182: Pcs

Sheet pending
A2: Tgl Faktur | B2: No. Faktur | C2: Code Cust. | D2: Code Brg | E2: Nama Barang | F2: Qty | G2: Sat | H2: Trx | I2: Batch | J2: Expired Date | K2: validas
A3: 45464 | B3: D24007614 | C3: PRIM03 | D3: QJAGU03 | E3: Jagung Bisi 18 20 X 1 kg | F3: 2000 | G3: Pack | H3: SJ | I3: 3095HBS18 | J3: 45574 | K3: Benih Jagung
A4: 44645 | B4: D22002298 | C4: KARI09 | D4: QGEMB01 | E4: Gembor GL-10A 12 X 10 ltr | F4: 4 | G4: Pcs | H4: SJ | I4: 0,00E+00 | J4: 01/01/1000 | K4: #N/A
A5: 45464 | B5: B24007456 | C5: BUKI01 | D5: QJAGU04 | E5: Jagung Bisi 2 20 X 1 kg | F5: 100 | G5: Pack | H5: SJ | I5: 2305HBS2 | J5: 45773 | K5: Benih Jagung
A6: 44930 | B6: D23000060A | C6: MITR54 | D6: QSPRA42 | E6: Sprayer Elektrik Bonanza 13.7 ltr | F6: 7 | G6: Pcs | H6: SJ | I6: 0,00E+00 | J6: 01/01/1000 | K6: #N/A
A7: 45461 | B7: D24007379 | C7: MUNA01 | D7: QJAGU72 | E7: Jagung Bisi 321 20 X 1 kg (+Kaos) | F7: 140 | G7: Pack | H7: SJ | I7: 2381HBS321 | J7: 45798 | K7: Benih Jagung
A8: 45462 | B8: D24007473 | C8: TANI49 | D8: QJAGU72 | E8: Jagung Bisi 321 20 X 1 kg (+Kaos) | F8: 40 | G8: Pack | H8: SJ | I8: 2381HBS321 | J8: 45798 | K8: Benih Jagung
A9: 45462 | B9: B24007380 | C9: BERK18 | D9: QJAGU68 | E9: Jagung DK 771 20 X 1 kg (Bayer) | F9: 40 | G9: Pack | H9: SJ | I9: 9CFA012099 | J9: 45543 | K9: Benih Jagung
A10: 45462 | B10: D24007473 | C10: TANI49 | D10: QJAGU68 | E10: Jagung DK 771 20 X 1 kg (Bayer) | F10: 300 | G10: Pack | H10: SJ | I10: 9CFA012099 | J10: 45543 | K10: Benih Jagung
A11: 45464 | B11: D24007589 | C11: SUBU01 | D11: QJAGU68 | E11: Jagung DK 771 20 X 1 kg (Bayer) | F11: 500 | G11: Pack | H11: SJ | I11: 9CFA013003 | J11: 45582 | K11: Benih Jagung
A12: 45432 | B12: Z24000995 | C12: KARI09 | D12: QPRIM25 | E12: Prima-Clink 50 X 100 ml (sampel) | F12: 65 | G12: Btl | H12: SJ | I12: 570.012.000.000.000.000 | J12: 47239 | K12: #N/A
A13: 45462 | B13: D24007477 | C13: SUBU01 | D13: QJAGU58 | E13: Jagung NK 7202 20 X 1 kg | F13: 500 | G13: Pack | H13: SJ | I13: 19046175 | J13: 45666 | K13: Benih Jagung
A14: 45464 | B14: D24007575 | C14: SINA27 | D14: QJAGU58 | E14: Jagung NK 7202 20 X 1 kg | F14: 1140 | G14: Pack | H14: SJ | I14: 19046175 | J14: 45666 | K14: Benih Jagung
A15: 45462 | B15: B24007380 | C15: BERK18 | D15: QJAGU70 | E15: Jagung P27 Gajah 20 X 1 kg | F15: 40 | G15: Pack | H15: SJ | I15: 007CKMAFDNDC055 | J15: 45641 | K15: Benih Jagung
A16: 45464 | B16: B24007485 | C16: MUHA31 | D16: QJAGU70 | E16: Jagung P27 Gajah 20 X 1 kg | F16: 200 | G16: Pack | H16: SJ | I16: 007CKMAFDNDC055 | J16: 45641 | K16: Benih Jagung
A17: 45461 | B17: B24007329 | C17: TANI259 | D17: QABAC01 | E17: Abacell 18 EC 10 X 1 ltr | F17: 10 | G17: Btl | H17: SJ | I17: 1,01E+07 | J17: 46204 | K17: Obat
A18: 45462 | B18: D24007481 | C18: KARY02 | D18: QABAC01 | E18: Abacell 18 EC 10 X 1 ltr | F18: 100 | G18: Btl | H18: SJ | I18: 1,01E+07 | J18: 46204 | K18: Obat
A19: 45457 | B19: D24007297 | C19: PERT10 | D19: QNOXO10 | E19: Noxone 276 SL 20 X 1 ltr | F19: 40 | G19: Btl | H19: SJ | I19: P0823I0801 | J19: 46997 | K19: #N/A
A20: 45463 | B20: B24007439 | C20: LANG01 | D20: QABAC01 | E20: Abacell 18 EC 10 X 1 ltr | F20: 9 | G20: Btl | H20: SJ | I20: 1,01E+07 | J20: 46204 | K20: Obat
A21: 45463 | B21: D24007522 | C21: LANG01 | D21: QABAC01 | E21: Abacell 18 EC 10 X 1 ltr | F21: 140 | G21: Btl | H21: SJ | I21: 1,01E+07 | J21: 46204 | K21: Obat
A22: 45461 | B22: B24007329 | C22: TANI259 | D22: QABAC04 | E22: Abacell 18 EC 40 X 250 ml | F22: 40 | G22: Btl | H22: SJ | I22: 5,12E+06 | J22: 46357 | K22: Obat
A23: 45463 | B23: B24007439 | C23: LANG01 | D23: QABAC04 | E23: Abacell 18 EC 40 X 250 ml | F23: 40 | G23: Btl | H23: SJ | I23: 5,12E+06 | J23: 46357 | K23: Obat
A24: 45463 | B24: D24007522 | C24: LANG01 | D24: QABAC04 | E24: Abacell 18 EC 40 X 250 ml | F24: 120 | G24: Btl | H24: SJ | I24: 5,12E+06 | J24: 46357 | K24: Obat
A25: 45464 | B25: B24007466 | C25: HART04 | D25: QABAC04 | E25: Abacell 18 EC 40 X 250 ml | F25: 5 | G25: Btl | H25: SJ | I25: 5,12E+06 | J25: 46357 | K25: Obat
A26: 45464 | B26: D24007613 | C26: SUBK01 | D26: QABAC04 | E26: Abacell 18 EC 40 X 250 ml | F26: 80 | G26: Btl | H26: SJ | I26: 5,12E+06 | J26: 46357 | K26: Obat
A27: 45465 | B27: B24007501 | C27: ARTH04 | D27: QABAC04 | E27: Abacell 18 EC 40 X 250 ml | F27: 80 | G27: Btl | H27: SJ | I27: 5,12E+06 | J27: 46357 | K27: Obat
A28: 45464 | B28: D24007613 | C28: SUBK01 | D28: QABAC07 | E28: Abacell 18 EC 50 X 100 ml | F28: 100 | G28: Btl | H28: SJ | I28: 3,00E+07 | J28: 46082 | K28: Obat
A29: 45458 | B29: D24007355 | C29: TANI57 | D29: QABEN01 | E29: Abenz 22 EC 100 X 100 ml | F29: 500 | G29: Btl | H29: SJ | I29: ADV0710180723 | J29: 46935 | K29: Obat
A30: 45458 | B30: D24007355 | C30: TANI57 | D30: QABEN02 | E30: Abenz 22 EC 40 X 250 ml | F30: 200 | G30: Btl | H30: SJ | I30: ADV261V050 | J30: 46997 | K30: Obat
A31: 45462 | B31: B24007356 | C31: SUCI01 | D31: QABEN02 | E31: Abenz 22 EC 40 X 250 ml | F31: 40 | G31: Btl | H31: SJ | I31: ADV261V050 | J31: 46997 | K31: Obat
... A74: 45461 | B74: D24007385 | C74: TANI224 | D74: QAVID01 | E74: Avidor 25 WP 4 X 25 X 100 gr | F74: 100 | G74: Pack | H74: SJ | I74: 4,20E+07 | J74: 47209 | K74: Obat
A75: 45462 | B75: B24007384 | C75: KARI09 | D75: QICEM02 | E75: Icemut 0.25 GR 4 X 25 X 20 gr | F75: 56 | G75: Pack | H75: SJ | I75: 0,00E+00 | J75: 01/01/1000 | K75: #N/A
A76: 45462 | B76: B24007385 | C76: KARI09 | D76: QICEM02 | E76: Icemut 0.25 GR 4 X 25 X 20 gr | F76: 400 | G76: Pack | H76: SJ | I76: 0,00E+00 | J76: 01/01/1000 | K76: #N/A
A77: 45462 | B77: B24007386 | C77: KARI09 | D77: QICEM02 | E77: Icemut 0.25 GR 4 X 25 X 20 gr | F77: 400 | G77: Pack | H77: SJ | I77: 0,00E+00 | J77: 01/01/1000 | K77: #N/A
A78: 45462 | B78: B24007387 | C78: KARI09 | D78: QICEM02 | E78: Icemut 0.25 GR 4 X 25 X 20 gr | F78: 400 | G78: Pack | H78: SJ | I78: 0,00E+00 | J78: 01/01/1000 | K78: #N/A
A79: 45462 | B79: B24007388 | C79: KARI09 | D79: QICEM02 | E79: Icemut 0.25 GR 4 X 25 X 20 gr | F79: 400 | G79: Pack | H79: SJ | I79: 0,00E+00 | J79: 01/01/1000 | K79: #N/A
A80: 45462 | B80: B24007383 | C80: KARI09 | D80: QICEM01 | E80: Icemut 0.25 GR 5 X 108 X 20 gr | F80: 186 | G80: Pack | H80: SJ | I80: 0,00E+00 | J80: 01/01/1000 | K80: #N/A
A81: 45462 | B81: B24007384 | C81: KARI09 | D81: QICEM01 | E81: Icemut 0.25 GR 5 X 108 X 20 gr | F81: 131 | G81: Pack | H81: SJ | I81: 0 | J81: 01/01/1000 | K81: #N/A
A82: 45464 | B82: B24007493 | C82: SARA06 | D82: QAVID01 | E82: Avidor 25 WP 4 X 25 X 100 gr | F82: 500 | G82: Pack | H82: SJ | I82: 42.024.001 | J82: 47209 | K82: Obat
A83: 45461 | B83: D24007385 | C83: TANI224 | D83: QBAME01 | E83: Bamex 18 EC 100 X 50 ml (M2U) | F83: 25 | G83: Btl | H83: SJ | I83: 12163201 | J83: 46204 | K83: Obat
...

Sheet Sheet2
D2: Gembor GL-10A 12 X 10 ltr | E2: 01/01/1000
D3: Icemut 0.25 GR 4 X 25 X 20 gr | E3: 01/01/1000
D4: Icemut 0.25 GR 5 X 108 X 20 gr | E4: 01/01/1000
D5: Noxone 276 SL 20 X 1 ltr | E5: 46997
D6: Noxone 276 SL 20 X 1 ltr | E6: 47239
